Workbook

Sheet Sheet1

Sheet Beta calculation
A1: SOCEP | M1: BVB
A2: 45961 | B2: 0 | E2: BETA | F2: =_xlfn.COVARIANCE.S(B2:B262,N2:N262)/_xlfn.VAR.S(N2:N262) -> 0.88044935 | M2: 45961 | N2: 0.0050632911
A3: 45954 | B3: 0 | M3: 45954 | N3: 0.0050890585
A4: 45947 | B4: -0.0061349693 | M4: 45947 | N4: -0.0075757576
A5: 45940 | B5: -0.006097561 | M5: 45940 | N5: 0.0076335878
A6: 45933 | B6: -0.0060606061 | M6: 45933 | N6: 0.0051150895
A7: 45926 | B7: -0.017857143 | M7: 45926 | N7: -0.010126582
A8: 45919 | B8: 0.024390244 | M8: 45919 | N8: -0.0125
A9: 45912 | B9: -0.026706231 | M9: 45912 | N9: -0.0024937656
A10: 45905 | B10: 0.0029761905 | M10: 45905 | N10: 0.0025
A11: 45898 | B11: -0.0059171598 | M11: 45898 | N11: 0.020408163
A12: 45891 | B12: -0.0029498525 | M12: 45891 | N12: -0.055421687
A13: 45884 | B13: 0.0059347181 | M13: 45884 | N13: -0.041570439
A14: 45877 | B14: 0.021212121 | M14: 45877 | N14: 0.0093240093
... A262: 44141 | B262: 0 | M262: 44141 | N262: 0

Sheet ERPs by country
A1: Country and Equity Risk Premiums
A2: Date of update: | B2: 44377
A3: Enter the current risk premium for a mature equity market | E3: 0.0421 | F3: Implied ERP for S&P 500 with adjusted dollar riskfree rate (for US Aa1 rating
A4: Do you want to adjust the country default spread for the additional volatility of the equity market to get to a country premium? | E4: Yes
A5: If yes, enter the multiplier to use on the default spread (See worksheet for volatility numbers for selected emerging markets) | E5: ='[1]Relative Equity Volatility'!D7 -> 1.5045643 | F5: See "Relative Equity Volatilty" worksheet
A7: Country | B7: Africa | C7: Moody's rating | D7: Rating-based Default Spread | E7: Total Equity Risk Premium | F7: Country Risk Premium | G7: Sovereign CDS, net of Swiss CDS | H7: Total Equity Risk Premium2 | I7: Country Risk Premium3 | J7: Has to be sorted in ascending order
A8: ='[1]Sovereign Ratings (Moody''s,S&P)'!A2 -> Abu Dhabi | B8: =VLOOKUP(A8,'[1]Regional lookup table'!$A$2:$B$162,2,FALSE) -> Middle East | C8: =VLOOKUP(A8,'[1]Sovereign Ratings (Moody''s,S&P)'!$A$2:$D$158,4,FALSE) -> Aa2 | D8: =VLOOKUP(C8,$J$9:$K$31,2,FALSE)/10000 -> 0.004853551 | E8: =$E$3+F8 -> 0.04940248 | F8: =IF($E$4="Yes",D8*$E$5,D8) -> 0.0073024796 | G8: =VLOOKUP(A8,'[1]10-year CDS Spreads'!$A$2:$D$158,4,FALSE) -> 0.0051 | H8: =IF(I8="NA","NA",$E$3+I8) -> 0.049773278 | I8: =IF(G8="NA","NA",G8*$E$5) -> 0.0076732779 | J8: Rating | K8: Default spread in basis points
A9: ='[1]Sovereign Ratings (Moody''s,S&P)'!A3 -> Albania | B9: =VLOOKUP(A9,'[1]Regional lookup table'!$A$2:$B$162,2,FALSE) -> Eastern Europe & Russia | C9: =VLOOKUP(A9,'[1]Sovereign Ratings (Moody''s,S&P)'!$A$2:$D$158,4,FALSE) -> Ba3 | D9: =VLOOKUP(C9,$J$9:$K$31,2,FALSE)/10000 -> 0.035361586 | E9: =$E$3+F9 -> 0.09530378 | F9: =IF($E$4="Yes",D9*$E$5,D9) -> 0.05320378 | G9: =VLOOKUP(A9,'[1]10-year CDS Spreads'!$A$2:$D$158,4,FALSE) -> NA | H9: =IF(I9="NA","NA",$E$3+I9) -> NA | I9: =IF(G9="NA","NA",G9*$E$5) -> NA | J9: A1 | K9: =C190 -> 69.336444
A10: ='[1]Sovereign Ratings (Moody''s,S&P)'!A4 -> Andorra (Principality of) | B10: =VLOOKUP(A10,'[1]Regional lookup table'!$A$2:$B$162,2,FALSE) -> Western Europe | C10: =VLOOKUP(A10,'[1]Sovereign Ratings (Moody''s,S&P)'!$A$2:$D$158,4,FALSE) -> Baa1 | D10: =VLOOKUP(C10,$J$9:$K$31,2,FALSE)/10000 -> 0.015716261 | E10: =$E$3+F10 -> 0.065746125 | F10: =IF($E$4="Yes",D10*$E$5,D10) -> 0.023646125 | G10: =VLOOKUP(A10,'[1]10-year CDS Spreads'!$A$2:$D$158,4,FALSE) -> NA | H10: =IF(I10="NA","NA",$E$3+I10) -> NA | I10: =IF(G10="NA","NA",G10*$E$5) -> NA | J10: A2 | K10: =C191 -> 83.203732
A11: ='[1]Sovereign Ratings (Moody''s,S&P)'!A5 -> Angola | B11: =VLOOKUP(A11,'[1]Regional lookup table'!$A$2:$B$162,2,FALSE) -> Africa | C11: =VLOOKUP(A11,'[1]Sovereign Ratings (Moody''s,S&P)'!$A$2:$D$158,4,FALSE) -> B3 | D11: =VLOOKUP(C11,$J$9:$K$31,2,FALSE)/10000 -> 0.063905089 | E11: =$E$3+F11 -> 0.13824932 | F11: =IF($E$4="Yes",D11*$E$5,D11) -> 0.096149315 | G11: =VLOOKUP(A11,'[1]10-year CDS Spreads'!$A$2:$D$158,4,FALSE) -> 0.0699 | H11: =IF(I11="NA","NA",$E$3+I11) -> 0.14726904 | I11: =IF(G11="NA","NA",G11*$E$5) -> 0.10516904 | J11: A3 | K11: =C192 -> 117.87195
A12: ='[1]Sovereign Ratings (Moody''s,S&P)'!A6 -> Argentina | B12: =VLOOKUP(A12,'[1]Regional lookup table'!$A$2:$B$162,2,FALSE) -> Central and South America | C12: =VLOOKUP(A12,'[1]Sovereign Ratings (Moody''s,S&P)'!$A$2:$D$158,4,FALSE) -> Caa3 | D12: =VLOOKUP(C12,$J$9:$K$31,2,FALSE)/10000 -> 0.098342189 | E12: =$E$3+F12 -> 0.19006215 | F12: =IF($E$4="Yes",D12*$E$5,D12) -> 0.14796215 | G12: =VLOOKUP(A12,'[1]10-year CDS Spreads'!$A$2:$D$158,4,FALSE) -> NA | H12: =IF(I12="NA","NA",$E$3+I12) -> NA | I12: =IF(G12="NA","NA",G12*$E$5) -> NA | J12: Aa1 | K12: =C193 -> 27
A13: ='[1]Sovereign Ratings (Moody''s,S&P)'!A7 -> Armenia | B13: =VLOOKUP(A13,'[1]Regional lookup table'!$A$2:$B$162,2,FALSE) -> Eastern Europe & Russia | C13: =VLOOKUP(A13,'[1]Sovereign Ratings (Moody''s,S&P)'!$A$2:$D$158,4,FALSE) -> Ba3 | D13: =VLOOKUP(C13,$J$9:$K$31,2,FALSE)/10000 -> 0.035361586 | E13: =$E$3+F13 -> 0.09530378 | F13: =IF($E$4="Yes",D13*$E$5,D13) -> 0.05320378 | G13: =VLOOKUP(A13,'[1]10-year CDS Spreads'!$A$2:$D$158,4,FALSE) -> NA | H13: =IF(I13="NA","NA",$E$3+I13) -> NA | I13: =IF(G13="NA","NA",G13*$E$5) -> NA | J13: Aa2 | K13: =C194 -> 48.53551
A14: ='[1]Sovereign Ratings (Moody''s,S&P)'!A8 -> Aruba | B14: =VLOOKUP(A14,'[1]Regional lookup table'!$A$2:$B$162,2,FALSE) -> Caribbean | C14: =VLOOKUP(A14,'[1]Sovereign Ratings (Moody''s,S&P)'!$A$2:$D$158,4,FALSE) -> Baa3 | D14: =VLOOKUP(C14,$J$9:$K$31,2,FALSE)/10000 -> 0.021609858 | E14: =$E$3+F14 -> 0.074613421 | F14: =IF($E$4="Yes",D14*$E$5,D14) -> 0.032513421 | G14: =VLOOKUP(A14,'[1]10-year CDS Spreads'!$A$2:$D$158,4,FALSE) -> NA | H14: =IF(I14="NA","NA",$E$3+I14) -> NA | I14: =IF(G14="NA","NA",G14*$E$5) -> NA | J14: Aa3 | K14: =C195 -> 58.935977
A15: ='[1]Sovereign Ratings (Moody''s,S&P)'!A9 -> Australia | B15: =VLOOKUP(A15,'[1]Regional lookup table'!$A$2:$B$162,2,FALSE) -> Australia & New Zealand | C15: =VLOOKUP(A15,'[1]Sovereign Ratings (Moody''s,S&P)'!$A$2:$D$158,4,FALSE) -> Aaa | D15: =VLOOKUP(C15,$J$9:$K$31,2,FALSE)/10000 -> 0 | E15: =$E$3+F15 -> 0.0421 | F15: =IF($E$4="Yes",D15*$E$5,D15) -> 0 | G15: =VLOOKUP(A15,'[1]10-year CDS Spreads'!$A$2:$D$158,4,FALSE) -> 0.0001 | H15: =IF(I15="NA","NA",$E$3+I15) -> 0.042250456 | I15: =IF(G15="NA","NA",G15*$E$5) -> 0.00015045643 | J15: Aaa | K15: =C196 -> 0
A16: ='[1]Sovereign Ratings (Moody''s,S&P)'!A10 -> Austria | B16: =VLOOKUP(A16,'[1]Regional lookup table'!$A$2:$B$162,2,FALSE) -> Western Europe | C16: =VLOOKUP(A16,'[1]Sovereign Ratings (Moody''s,S&P)'!$A$2:$D$158,4,FALSE) -> Aa1 | D16: =VLOOKUP(C16,$J$9:$K$31,2,FALSE)/10000 -> 0.0027 | E16: =$E$3+F16 -> 0.046162324 | F16: =IF($E$4="Yes",D16*$E$5,D16) -> 0.0040623236 | G16: =VLOOKUP(A16,'[1]10-year CDS Spreads'!$A$2:$D$158,4,FALSE) -> 0.0015 | H16: =IF(I16="NA","NA",$E$3+I16) -> 0.044356846 | I16: =IF(G16="NA","NA",G16*$E$5) -> 0.0022568465 | J16: B1 | K16: =C197 -> 442.59763
A17: ='[1]Sovereign Ratings (Moody''s,S&P)'!A11 -> Azerbaijan | B17: =VLOOKUP(A17,'[1]Regional lookup table'!$A$2:$B$162,2,FALSE) -> Eastern Europe & Russia | C17: =VLOOKUP(A17,'[1]Sovereign Ratings (Moody''s,S&P)'!$A$2:$D$158,4,FALSE) -> Baa3 | D17: =VLOOKUP(C17,$J$9:$K$31,2,FALSE)/10000 -> 0.021609858 | E17: =$E$3+F17 -> 0.074613421 | F17: =IF($E$4="Yes",D17*$E$5,D17) -> 0.032513421 | G17: =VLOOKUP(A17,'[1]10-year CDS Spreads'!$A$2:$D$158,4,FALSE) -> NA | H17: =IF(I17="NA","NA",$E$3+I17) -> NA | I17: =IF(G17="NA","NA",G17*$E$5) -> NA | J17: B2 | K17: =C198 -> 540.82426
A18: ='[1]Sovereign Ratings (Moody''s,S&P)'!A12 -> Bahamas | B18: =VLOOKUP(A18,'[1]Regional lookup table'!$A$2:$B$162,2,FALSE) -> Caribbean | C18: =VLOOKUP(A18,'[1]Sovereign Ratings (Moody''s,S&P)'!$A$2:$D$158,4,FALSE) -> B1 | D18: =VLOOKUP(C18,$J$9:$K$31,2,FALSE)/10000 -> 0.044259763 | E18: =$E$3+F18 -> 0.10869166 | F18: =IF($E$4="Yes",D18*$E$5,D18) -> 0.06659166 | G18: =VLOOKUP(A18,'[1]10-year CDS Spreads'!$A$2:$D$158,4,FALSE) -> NA | H18: =IF(I18="NA","NA",$E$3+I18) -> NA | I18: =IF(G18="NA","NA",G18*$E$5) -> NA | J18: B3 | K18: =C199 -> 639.05089
A19: ='[1]Sovereign Ratings (Moody''s,S&P)'!A13 -> Bahrain | B19: =VLOOKUP(A19,'[1]Regional lookup table'!$A$2:$B$162,2,FALSE) -> Middle East | C19: =VLOOKUP(A19,'[1]Sovereign Ratings (Moody''s,S&P)'!$A$2:$D$158,4,FALSE) -> B2 | D19: =VLOOKUP(C19,$J$9:$K$31,2,FALSE)/10000 -> 0.054082426 | E19: =$E$3+F19 -> 0.12347049 | F19: =IF($E$4="Yes",D19*$E$5,D19) -> 0.081370487 | G19: =VLOOKUP(A19,'[1]10-year CDS Spreads'!$A$2:$D$158,4,FALSE) -> 0.0262 | H19: =IF(I19="NA","NA",$E$3+I19) -> 0.081519585 | I19: =IF(G19="NA","NA",G19*$E$5) -> 0.039419585 | J19: Ba1 | K19: =C200 -> 246.14437
A20: ='[1]Sovereign Ratings (Moody''s,S&P)'!A14 -> Bangladesh | B20: =VLOOKUP(A20,'[1]Regional lookup table'!$A$2:$B$162,2,FALSE) -> Asia | C20: =VLOOKUP(A20,'[1]Sovereign Ratings (Moody''s,S&P)'!$A$2:$D$158,4,FALSE) -> B2 | D20: =VLOOKUP(C20,$J$9:$K$31,2,FALSE)/10000 -> 0.054082426 | E20: =$E$3+F20 -> 0.12347049 | F20: =IF($E$4="Yes",D20*$E$5,D20) -> 0.081370487 | G20: =VLOOKUP(A20,'[1]10-year CDS Spreads'!$A$2:$D$158,4,FALSE) -> NA | H20: =IF(I20="NA","NA",$E$3+I20) -> NA | I20: =IF(G20="NA","NA",G20*$E$5) -> NA | J20: Ba2 | K20: =C201 -> 295.83549
... A26: ='[1]Sovereign Ratings (Moody''s,S&P)'!A20 -> Bermuda | B26: =VLOOKUP(A26,'[1]Regional lookup table'!$A$2:$B$162,2,FALSE) -> Caribbean | C26: =VLOOKUP(A26,'[1]Sovereign Ratings (Moody''s,S&P)'!$A$2:$D$158,4,FALSE) -> A2 | D26: =VLOOKUP(C26,$J$9:$K$31,2,FALSE)/10000 -> 0.0083203732 | E26: =$E$3+F26 -> 0.054618537 | F26: =IF($E$4="Yes",D26*$E$5,D26) -> 0.012518537 | G26: =VLOOKUP(A26,'[1]10-year CDS Spreads'!$A$2:$D$158,4,FALSE) -> NA | H26: =IF(I26="NA","NA",$E$3+I26) -> NA | I26: =IF(G26="NA","NA",G26*$E$5) -> NA | J26: Ca | K26: =C207 -> 1179.8751
A27: ='[1]Sovereign Ratings (Moody''s,S&P)'!A21 -> Bolivia | B27: =VLOOKUP(A27,'[1]Regional lookup table'!$A$2:$B$162,2,FALSE) -> Central and South America | C27: =VLOOKUP(A27,'[1]Sovereign Ratings (Moody''s,S&P)'!$A$2:$D$158,4,FALSE) -> Ca | D27: =VLOOKUP(C27,$J$9:$K$31,2,FALSE)/10000 -> 0.11798751 | E27: =$E$3+F27 -> 0.2196198 | F27: =IF($E$4="Yes",D27*$E$5,D27) -> 0.1775198 | G27: =VLOOKUP(A27,'[1]10-year CDS Spreads'!$A$2:$D$158,4,FALSE) -> NA | H27: =IF(I27="NA","NA",$E$3+I27) -> NA | I27: =IF(G27="NA","NA",G27*$E$5) -> NA | J27: =B208 -> Caa1 | K27: =C208 -> 737.27752
A28: ='[1]Sovereign Ratings (Moody''s,S&P)'!A22 -> Bosnia and Herzegovina | B28: =VLOOKUP(A28,'[1]Regional lookup table'!$A$2:$B$162,2,FALSE) -> Eastern Europe & Russia | C28: =VLOOKUP(A28,'[1]Sovereign Ratings (Moody''s,S&P)'!$A$2:$D$158,4,FALSE) -> B3 | D28: =VLOOKUP(C28,$J$9:$K$31,2,FALSE)/10000 -> 0.063905089 | E28: =$E$3+F28 -> 0.13824932 | F28: =IF($E$4="Yes",D28*$E$5,D28) -> 0.096149315 | G28: =VLOOKUP(A28,'[1]10-year CDS Spreads'!$A$2:$D$158,4,FALSE) -> NA | H28: =IF(I28="NA","NA",$E$3+I28) -> NA | I28: =IF(G28="NA","NA",G28*$E$5) -> NA | J28: =B209 -> Caa2 | K28: =C209 -> 885.19526
A29: ='[1]Sovereign Ratings (Moody''s,S&P)'!A23 -> Botswana | B29: =VLOOKUP(A29,'[1]Regional lookup table'!$A$2:$B$162,2,FALSE) -> Africa | C29: =VLOOKUP(A29,'[1]Sovereign Ratings (Moody''s,S&P)'!$A$2:$D$158,4,FALSE) -> A3 | D29: =VLOOKUP(C29,$J$9:$K$31,2,FALSE)/10000 -> 0.011787195 | E29: =$E$3+F29 -> 0.059834593 | F29: =IF($E$4="Yes",D29*$E$5,D29) -> 0.017734593 | G29: =VLOOKUP(A29,'[1]10-year CDS Spreads'!$A$2:$D$158,4,FALSE) -> NA | H29: =IF(I29="NA","NA",$E$3+I29) -> NA | I29: =IF(G29="NA","NA",G29*$E$5) -> NA | J29: =B210 -> Caa3 | K29: =C210 -> 983.42189
A30: ='[1]Sovereign Ratings (Moody''s,S&P)'!A24 -> Brazil | B30: =VLOOKUP(A30,'[1]Regional lookup table'!$A$2:$B$162,2,FALSE) -> Central and South America | C30: =VLOOKUP(A30,'[1]Sovereign Ratings (Moody''s,S&P)'!$A$2:$D$158,4,FALSE) -> Ba1 | D30: =VLOOKUP(C30,$J$9:$K$31,2,FALSE)/10000 -> 0.024614437 | E30: =$E$3+F30 -> 0.079134004 | F30: =IF($E$4="Yes",D30*$E$5,D30) -> 0.037034004 | G30: =VLOOKUP(A30,'[1]10-year CDS Spreads'!$A$2:$D$158,4,FALSE) -> 0.0238 | H30: =IF(I30="NA","NA",$E$3+I30) -> 0.07790863 | I30: =IF(G30="NA","NA",G30*$E$5) -> 0.03580863 | J30: NR | K30: =C211 -> NA
A31: ='[1]Sovereign Ratings (Moody''s,S&P)'!A25 -> Bulgaria | B31: =VLOOKUP(A31,'[1]Regional lookup table'!$A$2:$B$162,2,FALSE) -> Eastern Europe & Russia | C31: =VLOOKUP(A31,'[1]Sovereign Ratings (Moody''s,S&P)'!$A$2:$D$158,4,FALSE) -> Baa1 | D31: =VLOOKUP(C31,$J$9:$K$31,2,FALSE)/10000 -> 0.015716261 | E31: =$E$3+F31 -> 0.065746125 | F31: =IF($E$4="Yes",D31*$E$5,D31) -> 0.023646125 | G31: =VLOOKUP(A31,'[1]10-year CDS Spreads'!$A$2:$D$158,4,FALSE) -> 0.0095 | H31: =IF(I31="NA","NA",$E$3+I31) -> 0.056393361 | I31: =IF(G31="NA","NA",G31*$E$5) -> 0.014293361
A32: ='[1]Sovereign Ratings (Moody''s,S&P)'!A26 -> Burkina Faso | B32: =VLOOKUP(A32,'[1]Regional lookup table'!$A$2:$B$162,2,FALSE) -> Africa | C32: =VLOOKUP(A32,'[1]Sovereign Ratings (Moody''s,S&P)'!$A$2:$D$158,4,FALSE) -> Caa1 | D32: =VLOOKUP(C32,$J$9:$K$31,2,FALSE)/10000 -> 0.073727752 | E32: =$E$3+F32 -> 0.15302814 | F32: =IF($E$4="Yes",D32*$E$5,D32) -> 0.11092814 | G32: =VLOOKUP(A32,'[1]10-year CDS Spreads'!$A$2:$D$158,4,FALSE) -> NA | H32: =IF(I32="NA","NA",$E$3+I32) -> NA | I32: =IF(G32="NA","NA",G32*$E$5) -> NA
A33: ='[1]Sovereign Ratings (Moody''s,S&P)'!A27 -> Cambodia | B33: =VLOOKUP(A33,'[1]Regional lookup table'!$A$2:$B$162,2,FALSE) -> Asia | C33: =VLOOKUP(A33,'[1]Sovereign Ratings (Moody''s,S&P)'!$A$2:$D$158,4,FALSE) -> B2 | D33: =VLOOKUP(C33,$J$9:$K$31,2,FALSE)/10000 -> 0.054082426 | E33: =$E$3+F33 -> 0.12347049 | F33: =IF($E$4="Yes",D33*$E$5,D33) -> 0.081370487 | G33: =VLOOKUP(A33,'[1]10-year CDS Spreads'!$A$2:$D$158,4,FALSE) -> NA | H33: =IF(I33="NA","NA",$E$3+I33) -> NA | I33: =IF(G33="NA","NA",G33*$E$5) -> NA
A34: ='[1]Sovereign Ratings (Moody''s,S&P)'!A28 -> Cameroon | B34: =VLOOKUP(A34,'[1]Regional lookup table'!$A$2:$B$162,2,FALSE) -> Africa | C34: =VLOOKUP(A34,'[1]Sovereign Ratings (Moody''s,S&P)'!$A$2:$D$158,4,FALSE) -> Caa1 | D34: =VLOOKUP(C34,$J$9:$K$31,2,FALSE)/10000 -> 0.073727752 | E34: =$E$3+F34 -> 0.15302814 | F34: =IF($E$4="Yes",D34*$E$5,D34) -> 0.11092814 | G34: =VLOOKUP(A34,'[1]10-year CDS Spreads'!$A$2:$D$158,4,FALSE) -> 0.0786 | H34: =IF(I34="NA","NA",$E$3+I34) -> 0.16035875 | I34: =IF(G34="NA","NA",G34*$E$5) -> 0.11825875
A35: ='[1]Sovereign Ratings (Moody''s,S&P)'!A29 -> Canada | B35: =VLOOKUP(A35,'[1]Regional lookup table'!$A$2:$B$162,2,FALSE) -> North America | C35: =VLOOKUP(A35,'[1]Sovereign Ratings (Moody''s,S&P)'!$A$2:$D$158,4,FALSE) -> Aaa | D35: =VLOOKUP(C35,$J$9:$K$31,2,FALSE)/10000 -> 0 | E35: =$E$3+F35 -> 0.0421 | F35: =IF($E$4="Yes",D35*$E$5,D35) -> 0 | G35: =VLOOKUP(A35,'[1]10-year CDS Spreads'!$A$2:$D$158,4,FALSE) -> 0.002 | H35: =IF(I35="NA","NA",$E$3+I35) -> 0.045109129 | I35: =IF(G35="NA","NA",G35*$E$5) -> 0.0030091286
A36: ='[1]Sovereign Ratings (Moody''s,S&P)'!A30 -> Cape Verde | B36: =VLOOKUP(A36,'[1]Regional lookup table'!$A$2:$B$162,2,FALSE) -> Africa | C36: =VLOOKUP(A36,'[1]Sovereign Ratings (Moody''s,S&P)'!$A$2:$D$158,4,FALSE) -> B2 | D36: =VLOOKUP(C36,$J$9:$K$31,2,FALSE)/10000 -> 0.054082426 | E36: =$E$3+F36 -> 0.12347049 | F36: =IF($E$4="Yes",D36*$E$5,D36) -> 0.081370487 | G36: =VLOOKUP(A36,'[1]10-year CDS Spreads'!$A$2:$D$158,4,FALSE) -> NA | H36: =IF(I36="NA","NA",$E$3+I36) -> NA | I36: =IF(G36="NA","NA",G36*$E$5) -> NA
A37: ='[1]Sovereign Ratings (Moody''s,S&P)'!A31 -> Cayman Islands | B37: =VLOOKUP(A37,'[1]Regional lookup table'!$A$2:$B$162,2,FALSE) -> Caribbean | C37: =VLOOKUP(A37,'[1]Sovereign Ratings (Moody''s,S&P)'!$A$2:$D$158,4,FALSE) -> Aa3 | D37: =VLOOKUP(C37,$J$9:$K$31,2,FALSE)/10000 -> 0.0058935977 | E37: =$E$3+F37 -> 0.050967297 | F37: =IF($E$4="Yes",D37*$E$5,D37) -> 0.0088672967 | G37: =VLOOKUP(A37,'[1]10-year CDS Spreads'!$A$2:$D$158,4,FALSE) -> NA | H37: =IF(I37="NA","NA",$E$3+I37) -> NA | I37: =IF(G37="NA","NA",G37*$E$5) -> NA
A38: ='[1]Sovereign Ratings (Moody''s,S&P)'!A32 -> Chile | B38: =VLOOKUP(A38,'[1]Regional lookup table'!$A$2:$B$162,2,FALSE) -> Central and South America | C38: =VLOOKUP(A38,'[1]Sovereign Ratings (Moody''s,S&P)'!$A$2:$D$158,4,FALSE) -> A2 | D38: =VLOOKUP(C38,$J$9:$K$31,2,FALSE)/10000 -> 0.0083203732 | E38: =$E$3+F38 -> 0.054618537 | F38: =IF($E$4="Yes",D38*$E$5,D38) -> 0.012518537 | G38: =VLOOKUP(A38,'[1]10-year CDS Spreads'!$A$2:$D$158,4,FALSE) -> 0.0087 | H38: =IF(I38="NA","NA",$E$3+I38) -> 0.055189709 | I38: =IF(G38="NA","NA",G38*$E$5) -> 0.013089709
A39: ='[1]Sovereign Ratings (Moody''s,S&P)'!A33 -> China | B39: =VLOOKUP(A39,'[1]Regional lookup table'!$A$2:$B$162,2,FALSE) -> Asia | C39: =VLOOKUP(A39,'[1]Sovereign Ratings (Moody''s,S&P)'!$A$2:$D$158,4,FALSE) -> A1 | D39: =VLOOKUP(C39,$J$9:$K$31,2,FALSE)/10000 -> 0.0069336444 | E39: =$E$3+F39 -> 0.052532114 | F39: =IF($E$4="Yes",D39*$E$5,D39) -> 0.010432114 | G39: =VLOOKUP(A39,'[1]10-year CDS Spreads'!$A$2:$D$158,4,FALSE) -> 0.0058 | H39: =IF(I39="NA","NA",$E$3+I39) -> 0.050826473 | I39: =IF(G39="NA","NA",G39*$E$5) -> 0.0087264729
A40: ='[1]Sovereign Ratings (Moody''s,S&P)'!A34 -> Colombia | B40: =VLOOKUP(A40,'[1]Regional lookup table'!$A$2:$B$162,2,FALSE) -> Central and South America | C40: =VLOOKUP(A40,'[1]Sovereign Ratings (Moody''s,S&P)'!$A$2:$D$158,4,FALSE) -> Baa3 | D40: =VLOOKUP(C40,$J$9:$K$31,2,FALSE)/10000 -> 0.021609858 | E40: =$E$3+F40 -> 0.074613421 | F40: =IF($E$4="Yes",D40*$E$5,D40) -> 0.032513421 | G40: =VLOOKUP(A40,'[1]10-year CDS Spreads'!$A$2:$D$158,4,FALSE) -> 0.0331 | H40: =IF(I40="NA","NA",$E$3+I40) -> 0.091901078 | I40: =IF(G40="NA","NA",G40*$E$5) -> 0.049801078
A41: ='[1]Sovereign Ratings (Moody''s,S&P)'!A35 -> Congo (Democratic Republic of) | B41: =VLOOKUP(A41,'[1]Regional lookup table'!$A$2:$B$162,2,FALSE) -> Africa | C41: =VLOOKUP(A41,'[1]Sovereign Ratings (Moody''s,S&P)'!$A$2:$D$158,4,FALSE) -> B3 | D41: =VLOOKUP(C41,$J$9:$K$31,2,FALSE)/10000 -> 0.063905089 | E41: =$E$3+F41 -> 0.13824932 | F41: =IF($E$4="Yes",D41*$E$5,D41) -> 0.096149315 | G41: =VLOOKUP(A41,'[1]10-year CDS Spreads'!$A$2:$D$158,4,FALSE) -> NA | H41: =IF(I41="NA","NA",$E$3+I41) -> NA | I41: =IF(G41="NA","NA",G41*$E$5) -> NA
A42: ='[1]Sovereign Ratings (Moody''s,S&P)'!A36 -> Congo (Republic of) | B42: =VLOOKUP(A42,'[1]Regional lookup table'!$A$2:$B$162,2,FALSE) -> Africa | C42: =VLOOKUP(A42,'[1]Sovereign Ratings (Moody''s,S&P)'!$A$2:$D$158,4,FALSE) -> Caa2 | D42: =VLOOKUP(C42,$J$9:$K$31,2,FALSE)/10000 -> 0.088519526 | E42: =$E$3+F42 -> 0.17528332 | F42: =IF($E$4="Yes",D42*$E$5,D42) -> 0.13318332 | G42: =VLOOKUP(A42,'[1]10-year CDS Spreads'!$A$2:$D$158,4,FALSE) -> NA | H42: =IF(I42="NA","NA",$E$3+I42) -> NA | I42: =IF(G42="NA","NA",G42*$E$5) -> NA
... A164: ='[1]Sovereign Ratings (Moody''s,S&P)'!A158 -> Zambia | B164: =VLOOKUP(A164,'[1]Regional lookup table'!$A$2:$B$162,2,FALSE) -> Africa | C164: =VLOOKUP(A164,'[1]Sovereign Ratings (Moody''s,S&P)'!$A$2:$D$158,4,FALSE) -> Caa2 | D164: =VLOOKUP(C164,$J$9:$K$31,2,FALSE)/10000 -> 0.088519526 | E164: =$E$3+F164 -> 0.17528332 | F164: =IF($E$4="Yes",D164*$E$5,D164) -> 0.13318332 | G164: =VLOOKUP(A164,'[1]10-year CDS Spreads'!$A$2:$D$158,4,FALSE) -> NA | H164: =IF(I164="NA","NA",$E$3+I164) -> NA | I164: =IF(G164="NA","NA",G164*$E$5) -> NA
A165: Frontier Markets (no sovereign ratings)
A166: Country | B166: PRS Composite Risk Score | C166: ERP | D166: CRP | E166: Default Spread
A167: ='[1]PRS Worksheet'!A162 -> Algeria | B167: ='[1]PRS Worksheet'!B162 -> 68.5 | C167: ='[1]PRS Worksheet'!E162 -> 0.09530378 | D167: ='[1]PRS Worksheet'!G162 -> 0.05320378 | E167: ='[1]PRS Worksheet'!D162 -> 0.035361586
...

Sheet Cost of equity
A1: 10y bond yield ron | B1: 0.0698
A2: Risk free rate | B2: =B1-B4 -> 0.0482
A3: Beta | B3: ='Beta calculation'!F2 -> 0.88044935
A4: CDS | B4: 0.0216
A5: ERP | B5: 0.0797
A6: Cost of equity | B6: =B2+B3*B5 -> 0.11837181
